Workbook

Sheet Acceso
A1: Platform or Equipment | B1: Associated Services to the platform | C1: Income / Dismount | D1: Responsable Technical Area | E1: Responsable Technician | F1: Year | G1: Technical Site | H1: City | I1: Regional | J1: Additional m2? Yes/No | K1: If Yes: # Racks? | L1: Quantity Equipment DC | M1: Average Power (W) | N1: Máx. Power DC (W) | O1: Potencia a liberar | P1: Voltage (AC or DC) | Q1: Air DissipationBTU | R1: Power sources | S1: Quantity Equipment AC | T1: Máx. Power AC (W) | U1: Voltage (AC or DC) | V1: Requested Area (M2) | W1: Instalation date | X1: Priority | Y1: Comments (Área Ingeniería)
A4: Plataforma OLT Equipo Nuevo | B4: BBI-TV-TOIP | C4: Income | D4: ACCESO FIJO | E4: Henry Campos | F4: 2023 | G4: Centro EDATEL | H4: Puerto Berrio | J4: Yes | K4: 2 | L4: 1 | M4: 842 | N4: 1403 | P4: DC | R4: 2 | S4: 0 | T4: 0 | U4: DC | V4: 3 | W4: Q2
A5: Plataforma OLT Equipo Nuevo | B5: BBI-TV-TOIP | C5: Income | D5: ACCESO FIJO | E5: Henry Campos | F5: 2023 | G5: Centro EDATEL | H5: Segovia | J5: Yes | K5: 2 | L5: 1 | M5: 842 | N5: 1403 | P5: DC | R5: 2 | S5: 0 | T5: 0 | U5: DC | V5: 3 | W5: Q2
A6: Plataforma OLT Equipo Nuevo | B6: BBI-TV-TOIP | C6: Income | D6: ACCESO FIJO | E6: Henry Campos | F6: 2023 | G6: Centro EDATEL | H6: Chigorodó | J6: Yes | K6: 2 | L6: 1 | M6: 842 | N6: 1403 | P6: DC | R6: 2 | S6: 0 | T6: 0 | U6: DC | V6: 3 | W6: Q2
A7: Plataforma OLT Equipo Nuevo | B7: BBI-TV-TOIP | C7: Income | D7: ACCESO FIJO | E7: Henry Campos | F7: 2023 | G7: Castilla | H7: MEDELLÍN | J7: Yes | K7: 2 | L7: 1 | M7: 842 | N7: 1403 | P7: DC | R7: 2 | S7: 0 | T7: 0 | U7: DC | V7: 3 | W7: Q1
A8: Plataforma OLT Equipo Nuevo | B8: BBI-TV-TOIP | C8: Income | D8: ACCESO FIJO | E8: Henry Campos | F8: 2023 | G8: Berlín | H8: MEDELLÍN | J8: Yes | K8: 2 | L8: 1 | M8: 842 | N8: 1403 | P8: DC | R8: 2 | S8: 0 | T8: 0 | U8: DC | V8: 3 | W8: Q1
A9: Plataforma OLT Equipo Nuevo | B9: BBI-TV-TOIP | C9: Income | D9: ACCESO FIJO | E9: Henry Campos | F9: 2023 | G9: Villa Hermosa | H9: MEDELLÍN | J9: Yes | K9: 2 | L9: 1 | M9: 842 | N9: 1403 | P9: DC | R9: 2 | S9: 0 | T9: 0 | U9: DC | V9: 3 | W9: Q1
A10: Plataforma OLT Equipo Nuevo | B10: BBI-TV-TOIP | C10: Income | D10: ACCESO FIJO | E10: Henry Campos | F10: 2023 | G10: Florencia | H10: MEDELLÍN | J10: Yes | K10: 2 | L10: 1 | M10: 842 | N10: 1403 | P10: DC | R10: 2 | S10: 0 | T10: 0 | U10: DC | V10: 3 | W10: Q1
A11: Plataforma OLT Equipo Nuevo | B11: BBI-TV-TOIP | C11: Income | D11: ACCESO FIJO | E11: Henry Campos | F11: 2023 | G11: Bosque | H11: MEDELLÍN | J11: Yes | K11: 2 | L11: 1 | M11: 842 | N11: 1403 | P11: DC | R11: 2 | S11: 0 | T11: 0 | U11: DC | V11: 3 | W11: Q1
A12: Plataforma OLT Equipo Nuevo | B12: BBI-TV-TOIP | C12: Income | D12: ACCESO FIJO | E12: Henry Campos | F12: 2023 | G12: Belén | H12: MANIZALES | J12: Yes | K12: 2 | L12: 1 | M12: 842 | N12: 1403 | P12: DC | R12: 2 | S12: 0 | T12: 0 | U12: DC | V12: 3 | W12: Q2
A13: Plataforma OLT Equipo Nuevo | B13: BBI-TV-TOIP | C13: Income | D13: ACCESO FIJO | E13: Henry Campos | F13: 2023 | G13: Centro | H13: BUGA | J13: Yes | K13: 2 | L13: 1 | M13: 842 | N13: 1403 | P13: DC | R13: 2 | S13: 0 | T13: 0 | U13: DC | V13: 3 | W13: Q2
A14: Plataforma OLT Equipo Nuevo | B14: BBI-TV-TOIP | C14: Income | D14: ACCESO FIJO | E14: Henry Campos | F14: 2023 | G14: Álamos | H14: Pereira | J14: Yes | K14: 2 | L14: 1 | M14: 842 | N14: 1403 | P14: DC | R14: 2 | S14: 0 | T14: 0 | U14: DC | V14: 3 | W14: Q2
A15: Plataforma OLT Equipo Nuevo | B15: BBI-TV-TOIP | C15: Income | D15: ACCESO FIJO | E15: Henry Campos | F15: 2023 | G15: San Francisco | H15: Bucaramanga | J15: Yes | K15: 2 | L15: 1 | M15: 842 | N15: 1403 | P15: DC | R15: 2 | S15: 0 | T15: 0 | U15: DC | V15: 3 | W15: Q2
... A45: Plataforma CMTS Tradicional Equipo Nuevo | B45: BBI-TV-TOIP | C45: Income | D45: ACCESO FIJO | E45: Juan Valdes | F45: 2023 | G45: Engativá | H45: Bogotá | J45: Yes | K45: 1 | L45: 1 | M45: 6000 | N45: 1500 | P45: DC | R45: 4 | S45: 0 | T45: 0 | U45: DC | V45: 1.5 | W45: Q2
A46: Plataforma Óptica | B46: BBI-TV-TOIP | C46: Income | D46: Gerencia Acceso Fijo | E46: Jorge Ivan Pérez Cardona | F46: 2023 | G46: Cantalejo | H46: Bogotá | J46: Yes | K46: 1 | L46: 6 | M46: 475 | N46: 2850 | P46: DC | Q46: 1620.75 | R46: 2 | U46: 48 VDC | V46: 1.5 | W46: Q1-Q2 | Y46: Transmisores y Receptotes Ópticos
A47: Plataforma Óptica | B47: BBI-TV-TOIP | C47: Income | D47: Gerencia Acceso Fijo | E47: Jorge Ivan Pérez Cardona | F47: 2023 | G47: Quinta Camacho | H47: Bogotá | J47: Yes | K47: 1 | L47: 6 | M47: 475 | N47: 2850 | P47: DC | Q47: 1620.75 | R47: 2 | U47: 48 VDC | V47: 1.5 | W47: Q1-Q2 | Y47: Transmisores y Receptotes Ópticos
A48: Plataforma Óptica | B48: BBI-TV-TOIP | C48: Income | D48: Gerencia Acceso Fijo | E48: Jorge Ivan Pérez Cardona | F48: 2023 | G48: El Carmen | H48: Bogotá | J48: Yes | K48: 1 | L48: 6 | M48: 475 | N48: 2850 | P48: DC | Q48: 1620.75 | R48: 2 | U48: 48 VDC | V48: 1.5 | W48: Q1-Q2 | Y48: Transmisores y Receptotes Ópticos
A49: Plataforma Óptica | B49: BBI-TV-TOIP | C49: Income | D49: Gerencia Acceso Fijo | E49: Jorge Ivan Pérez Cardona | F49: 2023 | G49: Engativa | H49: Bogotá | J49: Yes | K49: 1 | L49: 6 | M49: 475 | N49: 2850 | P49: DC | Q49: 1620.75 | R49: 2 | U49: 48 VDC | V49: 1.5 | W49: Q1-Q2 | Y49: Transmisores y Receptotes Ópticos
A50: Plataforma Óptica | B50: BBI-TV-TOIP | C50: Income | D50: Gerencia Acceso Fijo | E50: Jorge Ivan Pérez Cardona | F50: 2023 | G50: La Fragua | H50: Bogotá | J50: Yes | K50: 1 | L50: 6 | M50: 475 | N50: 2850 | P50: DC | Q50: 1620.75 | R50: 2 | U50: 48 VDC | V50: 1.5 | W50: Q1-Q2 | Y50: Transmisores y Receptotes Ópticos
A51: Plataforma Óptica | B51: BBI-TV-TOIP | C51: Income | D51: Gerencia Acceso Fijo | E51: Jorge Ivan Pérez Cardona | F51: 2023 | G51: La Paz (Bosa) | H51: Bogotá | J51: Yes | K51: 1 | L51: 6 | M51: 475 | N51: 2850 | P51: DC | Q51: 1620.75 | R51: 2 | U51: 48 VDC | V51: 1.5 | W51: Q1-Q2 | Y51: Transmisores y Receptotes Ópticos
A52: Plataforma Óptica | B52: BBI-TV-TOIP | C52: Income | D52: Gerencia Acceso Fijo | E52: Jorge Ivan Pérez Cardona | F52: 2023 | G52: Suba | H52: Bogotá | J52: Yes | K52: 1 | L52: 6 | M52: 475 | N52: 2850 | P52: DC | Q52: 1620.75 | R52: 2 | U52: 48 VDC | V52: 1.5 | W52: Q1-Q2 | Y52: Transmisores y Receptotes Ópticos
A53: Plataforma Óptica | B53: BBI-TV-TOIP | C53: Income | D53: Gerencia Acceso Fijo | E53: Jorge Ivan Pérez Cardona | F53: 2023 | G53: Timiza | H53: Bogotá | J53: Yes | K53: 1 | L53: 6 | M53: 475 | N53: 2850 | P53: DC | Q53: 1620.75 | R53: 2 | U53: 48 VDC | V53: 1.5 | W53: Q1-Q2 | Y53: Transmisores y Receptotes Ópticos
A54: Plataforma Óptica | B54: BBI-TV-TOIP | C54: Income | D54: Gerencia Acceso Fijo | E54: Jorge Ivan Pérez Cardona | F54: 2023 | G54: Montevídeo | H54: Bogotá | J54: Yes | K54: 1 | L54: 12 | M54: 475 | N54: 5700 | P54: DC | Q54: 1620.75 | R54: 2 | U54: 48 VDC | V54: 1.5 | W54: Q1-Q2 | Y54: Transmisores y Receptotes Ópticos
A55: Plataforma Óptica | B55: BBI-TV-TOIP | C55: Income | D55: Gerencia Acceso Fijo | E55: Jorge Ivan Pérez Cardona | F55: 2023 | G55: CAN | H55: Bogotá | J55: Yes | K55: 1 | L55: 6 | M55: 475 | N55: 2850 | P55: DC | Q55: 1620.75 | R55: 2 | U55: 48 VDC | V55: 1.5 | W55: Q1-Q2 | Y55: Transmisores y Receptotes Ópticos
A56: Plataforma Óptica | B56: BBI-TV-TOIP | C56: Income | D56: Gerencia Acceso Fijo | E56: Jorge Ivan Pérez Cardona | F56: 2023 | G56: Santa Bibiana | H56: Bogotá | J56: Yes | K56: 1 | L56: 6 | M56: 475 | N56: 2850 | P56: DC | Q56: 1620.75 | R56: 2 | U56: 48 VDC | V56: 1.5 | W56: Q1-Q2 | Y56: Transmisores y Receptotes Ópticos
A57: Plataforma Óptica | B57: BBI-TV-TOIP | C57: Income | D57: Gerencia Acceso Fijo | E57: Jorge Ivan Pérez Cardona | F57: 2023 | G57: Valladolid | H57: Bogotá | J57: Yes | K57: 1 | L57: 6 | M57: 475 | N57: 2850 | P57: DC | Q57: 1620.75 | R57: 2 | U57: 48 VDC | V57: 1.5 | W57: Q1-Q2 | Y57: Transmisores y Receptotes Ópticos
... A135: Plataforma Óptica | B135: BBI-TV-TOIP | C135: Income | D135: Gereencia Acceso Fijo | E135: Jorge Ivan Pérez Cardona | F135: 2023 | G135: Autopista | H135: Tunja | J135: Yes | K135: 1 | L135: 6 | M135: 475 | N135: 2850 | P135: DC | Q135: 1620.75 | R135: 2 | U135: 48 VDC | V135: 1.5 | W135: Q1-Q2 | Y135: Transmisores y Receptotes Ópticos

Sheet Transporte
A2: Platform or Equipment | B2: Associated Services to the platform | C2: Income / Dismount | D2: Responsable Technical Area | E2: Responsable Technician | F2: Year | G2: Technical Site | H2: City | I2: Regional | J2: Additional m2? Yes/No | K2: If Yes: # Racks? | L2: Quantity Equipment DC | M2: Average Power (W) | N2: Máx. Power DC (W) | O2: Potencia liberar | P2: Voltage (AC or DC) | Q2: Air DissipationBTU | R2: Power sources | S2: Quantity Equipment AC | T2: Máx. Power AC (W) | U2: Voltage (AC or DC) | V2: Requested Area (M2) | W2: Instalation date | X2: Prority | Y2: Comments
A3: DWDM Huawei | B3: Internet, datos, voz, B2B, TV | C3: Income | D3: Gerencia de Transporte | E3: Wilmar Moreno | F3: 2023 | G3: Bosque | H3: Cartagena | I3: Costa | J3: No | M3: 1191 | P3: DC | Q3: =M3*3.4121 -> 4063.8111 | U3: 48 VDC | Y3: Tarjetas en OSN9800U32 existente
A4: DWDM Huawei | B4: Internet, datos, voz, B2B, TV | C4: Income | D4: Gerencia de Transporte | E4: Wilmar Moreno | F4: 2023 | G4: Miraflores | H4: Medellín | I4: Nor occidente | J4: No | M4: 1898 | P4: DC | Q4: =M4*3.4121 -> 6476.1658 | U4: 48 VDC | Y4: Tarjetas en OSN9800U32 existente
A5: DWDM Huawei | B5: Internet, datos, voz, B2B, TV | C5: Income | D5: Gerencia de Transporte | E5: Wilmar Moreno | F5: 2023 | G5: Zona Sur MON004 | H5: Montería | I5: Costa | J5: No | M5: 858 | P5: DC | Q5: =M5*3.4121 -> 2927.5818 | U5: 48 VDC | Y5: Tarjetas en OSN9800U32 existente
A6: DWDM Huawei | B6: Internet, datos, voz, B2B, TV | C6: Income | D6: Gerencia de Transporte | E6: Wilmar Moreno | F6: 2023 | G6: 7 de agosto VAL005 | H6: Valledupar | I6: Costa | J6: Yes | K6: 1 | L6: 1 | M6: 1241 | N6: 2400 | P6: DC | Q6: =M6*3.4121 -> 4234.4161 | R6: 2+2 | U6: 48 VDC | V6: 0,3 x 0,6 | Y6: Tarjetas en OSN9800U32 existente 1 Rack y equipo OSN1800V nuevo
A7: DWDM Huawei | B7: Internet, datos, voz, B2B, TV | C7: Income | D7: Gerencia de Transporte | E7: Wilmar Moreno | F7: 2023 | G7: Anillo Vial | H7: Bucaramanga | I7: Oriente | J7: No | M7: 700 | P7: DC | Q7: =M7*3.4121 -> 2388.47 | U7: 48 VDC | Y7: Tarjetas en OSN9800U32 existente
A8: DWDM Huawei | B8: Internet, datos, voz, B2B, TV | C8: Income | D8: Gerencia de Transporte | E8: Wilmar Moreno | F8: 2023 | G8: Centro | H8: Manizales | I8: Eje Cafetero | J8: No | M8: =2328-1464 -> 864 | P8: DC | Q8: =M8*3.4121 -> 2948.0544 | U8: 48 VDC | Y8: Tarjetas en OSN9800U32 existente
A9: DWDM Huawei | B9: Internet, datos, voz, B2B, TV | C9: Income | D9: Gerencia de Transporte | E9: Wilmar Moreno | F9: 2023 | G9: Coliseo | H9: Pereira | I9: Eje Cafetero | J9: No | M9: 383 | P9: DC | Q9: =M9*3.4121 -> 1306.8343 | U9: 48 VDC | Y9: Tarjetas en OSN9800M24 existente
A10: DWDM Huawei | B10: Internet, datos, voz, B2B, TV | C10: Income | D10: Gerencia de Transporte | E10: Wilmar Moreno | F10: 2023 | G10: Centro | H10: Pereira | I10: Eje Cafetero | J10: No | M10: 766 | P10: DC | Q10: =M10*3.4121 -> 2613.6686 | U10: 48 VDC | Y10: Tarjetas en OSN9800M24 existente
A11: DWDM Huawei | B11: Internet, datos, voz, B2B, TV | C11: Income | D11: Gerencia de Transporte | E11: Wilmar Moreno | F11: 2023 | G11: Vasquez Cobo | H11: Cali | I11: Sur occidente | J11: No | M11: 542 | P11: DC | Q11: =M11*3.4121 -> 1849.3582 | U11: 48 VDC | Y11: Tarjetas en OSN9800M24 existente
A12: DWDM Huawei | B12: Internet, datos, voz, B2B, TV | C12: Income | D12: Gerencia de Transporte | E12: Wilmar Moreno | F12: 2023 | G12: Belén | H12: Manizales | I12: Eje Cafetero | J12: Yes | K12: 1 | L12: 1 | M12: 1788 | N12: 3874 | P12: DC | Q12: =M12*3.4121 -> 6100.8348 | R12: 2+2 | U12: 48 VDC | V12: 0,3 x 0,6 | Y12: 1 rack y equipo OSN9800M24 nuevo
A13: DWDM Huawei | B13: Internet, datos, voz, B2B, TV | C13: Income | D13: Gerencia de Transporte | E13: Wilmar Moreno | F13: 2023 | G13: La Ceja | H13: La Ceja | I13: Nor occidente | J13: No | L13: 1 | M13: =440+78 -> 518 | N13: 800 | P13: DC | Q13: =M13*3.4121 -> 1767.4678 | U13: 48 VDC | Y13: Tarjetas en OSN1800VPro existente 1 equipo OSN1800II TP Nuevo
A14: DWDM Huawei | B14: Internet, datos, voz, B2B, TV | C14: Income | D14: Gerencia de Transporte | E14: Wilmar Moreno | F14: 2023 | G14: El Burro CES0017 | H14: El Burro | I14: Costa | J14: No | M14: 172 | P14: DC | Q14: =M14*3.4121 -> 586.8812 | U14: 48 VDC | Y14: Tarjetas en 1800V existente
A15: DWDM Huawei | B15: Internet, datos, voz, B2B, TV | C15: Income | D15: Gerencia de Transporte | E15: Wilmar Moreno | F15: 2023 | G15: Caldas | H15: Caldas | I15: Nor occidente | J15: Yes | K15: 1 | L15: 1 | M15: 483 | N15: 2400 | P15: DC | Q15: =M15*3.4121 -> 1648.0443 | R15: 2+2 | U15: 48 VDC | V15: 0,3 x 0,6 | Y15: 1 rack y equipo OSN1800V nuevo
A16: DWDM Huawei | B16: Internet, datos, voz, B2B, TV | C16: Income | D16: Gerencia de Transporte | E16: Wilmar Moreno | F16: 2023 | G16: Host-EDATEL | H16: Sincelejo | I16: Costa | J16: No | M16: 208.4 | P16: DC | Q16: =M16*3.4121 -> 711.08164 | U16: 48 VDC | Y16: Tarjetas en OSN1800VPro existente
A17: DWDM Huawei | B17: Internet, datos, voz, B2B, TV | C17: Income | D17: Gerencia de Transporte | E17: Wilmar Moreno | F17: 2023 | G17: Host-EDATEL | H17: Corozal | I17: Costa | J17: No | M17: 74 | P17: DC | Q17: =M17*3.4121 -> 252.4954 | U17: 48 VDC | Y17: Tarjetas en OSN1800VPro existente
A18: DWDM Huawei | B18: Internet, datos, voz, B2B, TV | C18: Income | D18: Gerencia de Transporte | E18: Wilmar Moreno | F18: 2023 | G18: Host-EDATEL | H18: Magangué | I18: Costa | J18: No | M18: 172 | P18: DC | Q18: =M18*3.4121 -> 586.8812 | U18: 48 VDC | Y18: Tarjetas en OSN1800VPro existente
A19: DWDM Huawei | B19: Internet, datos, voz, B2B, TV | C19: Income | D19: Gerencia de Transporte | E19: Wilmar Moreno | F19: 2023 | G19: BOL0065 | H19: Mompox | I19: Costa | J19: No | M19: 172 | P19: DC | Q19: =M19*3.4121 -> 586.8812 | U19: 48 VDC | Y19: Tarjetas en OSN1800VPro existente
A20: DWDM Huawei | B20: Internet, datos, voz, B2B, TV | C20: Income | D20: Gerencia de Transporte | E20: Wilmar Moreno | F20: 2023 | G20: MAG0102 | H20: El Banco | I20: Costa | J20: No | M20: 172 | P20: DC | Q20: =M20*3.4121 -> 586.8812 | U20: 48 VDC | Y20: Tarjetas en OSN1800VPro existente
A21: DWDM Huawei | B21: Internet, datos, voz, B2B, TV | C21: Income | D21: Gerencia de Transporte | E21: Wilmar Moreno | F21: 2023 | G21: Host-EDATEL | H21: La Pintada | I21: Nor occidente | J21: No | M21: 572 | P21: DC | Q21: =M21*3.4121 -> 1951.7212 | U21: 48 VDC | Y21: Tarjetas en OSN1800VPro existente
A22: DWDM Huawei | B22: Internet, datos, voz, B2B, TV | C22: Income | D22: Gerencia de Transporte | E22: Wilmar Moreno | F22: 2023 | G22: Host-EDATEL | H22: Valparaiso | I22: Nor occidente | J22: No | M22: 74 | P22: DC | Q22: =M22*3.4121 -> 252.4954 | U22: 48 VDC | Y22: Tarjetas en OSN1800VPro existente
A23: DWDM Huawei | B23: Internet, datos, voz, B2B, TV | C23: Income | D23: Gerencia de Transporte | E23: Wilmar Moreno | F23: 2023 | G23: Host-EDATEL | H23: Tamesis | I23: Nor occidente | J23: No | M23: 74 | P23: DC | Q23: =M23*3.4121 -> 252.4954 | U23: 48 VDC | Y23: Tarjetas en OSN1800VPro existente
A24: DWDM Huawei | B24: Internet, datos, voz, B2B, TV | C24: Income | D24: Gerencia de Transporte | E24: Wilmar Moreno | F24: 2023 | G24: Host-EDATEL | H24: Jericó | I24: Nor occidente | J24: No | M24: 74 | P24: DC | Q24: =M24*3.4121 -> 252.4954 | U24: 48 VDC | Y24: Tarjetas en OSN1800VPro existente
A25: DWDM Huawei | B25: Internet, datos, voz, B2B, TV | C25: Income | D25: Gerencia de Transporte | E25: Wilmar Moreno | F25: 2023 | G25: Host-EDATEL | H25: Jardin | I25: Nor occidente | J25: No | M25: 74 | P25: DC | Q25: =M25*3.4121 -> 252.4954 | U25: 48 VDC | Y25: Tarjetas en OSN1800VPro existente
A26: DWDM Huawei | B26: Internet, datos, voz, B2B, TV | C26: Income | D26: Gerencia de Transporte | E26: Wilmar Moreno | F26: 2023 | G26: Host-EDATEL | H26: Andes | I26: Nor occidente | J26: No | M26: 74 | P26: DC | Q26: =M26*3.4121 -> 252.4954 | U26: 48 VDC | Y26: Tarjetas en OSN1800VPro existente
A27: DWDM Huawei | B27: Internet, datos, voz, B2B, TV | C27: Income | D27: Gerencia de Transporte | E27: Wilmar Moreno | F27: 2023 | G27: Host-EDATEL | H27: Amaga | I27: Nor occidente | J27: No | M27: 508 | P27: DC | Q27: =M27*3.4121 -> 1733.3468 | U27: 48 VDC | Y27: Tarjetas en OSN1800VPro existente
... A51: DWDM Nokia | B51: Internet, datos, voz, B2B, TV | C51: Income | D51: Gerencia de Transporte | E51: Wilmar Moreno | F51: 2023 | G51: Vasquez Cobo | H51: Cali | I51: Sur occidente | J51: No | M51: 530 | P51: DC | Q51: =M51*3.4121 -> 1808.413 | U51: 48 VDC | Y51: Tarjetas en equipos PSS32/36/64 existentes

Sheet MPLS
A1: Platform or Equipment | B1: Associated Services to the platform | C1: Income / Dismount | D1: Responsable Technical Area | E1: Responsable Technician | F1: Year | G1: Technical Site | H1: City | I1: Regional | J1: Additional m2? Yes/No | K1: If Yes: # Racks? | L1: Quantity Equipment DC | M1: Average Power (W) | N1: Máx. Power DC (W) | O1: Potencia liberar | P1: Voltage (AC or DC) | Q1: Air DissipationBTU | R1: Power sources | S1: Quantity Equipment AC | T1: Máx. Power AC (W) | U1: Voltage (AC or DC) | V1: Requested Area (M2) | W1: Instalation date | X1: Prority | Y1: Comments
A2: MPLS | B2: MPLS | C2: INCOME | D2: Cloud IP/MPLS | E2: José Alejandro Arcila | F2: 2023 | G2: Miraflores | H2: Medellín | J2: no | K2: 0 | L2: 0 | M2: 400 | N2: 600 | P2: dc | Q2: 682 BTU/hour | Y2: Tarjeta 2*100
A3: MPLS | B3: MPLS | C3: INCOME | D3: Cloud IP/MPLS | E3: José Alejandro Arcila | F3: 2023 | G3: Apartadó | H3: Apartadó | J3: no | K3: 0 | L3: 0 | M3: 400 | N3: 600 | P3: dc | Q3: 682 BTU/hour | Y3: Tarjeta 2*100
A4: MPLS | B4: MPLS | C4: INCOME | D4: Cloud IP/MPLS | E4: José Alejandro Arcila | F4: 2023 | G4: Montería | H4: Montería | J4: no | K4: 0 | L4: 0 | M4: 400 | N4: 600 | P4: dc | Q4: 682 BTU/hour | Y4: Tarjeta 24*10
A5: MPLS | B5: MPLS | C5: INCOME | D5: Cloud IP/MPLS | E5: José Alejandro Arcila | F5: 2023 | G5: Centro ejecutivo | H5: Santa Martha | J5: no | K5: 0 | L5: 0 | M5: 400 | N5: 600 | P5: dc | Q5: 682 BTU/hour | Y5: Tarjeta 24*10
A6: MPLS | B6: MPLS | C6: INCOME | D6: Cloud IP/MPLS | E6: José Alejandro Arcila | F6: 2023 | G6: Bello | H6: Bello | J6: no | K6: 0 | L6: 0 | M6: 400 | N6: 600 | P6: dc | Q6: 682 BTU/hour | Y6: Tarjeta 2*100G
A7: MPLS | B7: MPLS | C7: INCOME | D7: Cloud IP/MPLS | E7: José Alejandro Arcila | F7: 2023 | G7: Engativá | H7: Bogotá | J7: no | K7: 0 | L7: 0 | M7: 400 | N7: 600 | P7: dc | Q7: 682 BTU/hour | Y7: Tarjeta 2*100G
A8: MPLS | B8: MPLS | C8: INCOME | D8: Cloud IP/MPLS | E8: José Alejandro Arcila | F8: 2023 | G8: Buenos aires | H8: Medellín | J8: no | K8: 0 | L8: 0 | M8: 400 | N8: 600 | P8: dc | Q8: 682 BTU/hour | Y8: Tarjeta 2*100G
A9: MPLS | B9: MPLS | C9: INCOME | D9: Cloud IP/MPLS | E9: José Alejandro Arcila | F9: 2023 | G9: Bosque | H9: Medellín | J9: no | K9: 0 | L9: 0 | M9: 400 | N9: 600 | P9: dc | Q9: 682 BTU/hour | Y9: Tarjeta 2*100G
A10: MPLS | B10: MPLS | C10: INCOME | D10: Cloud IP/MPLS | E10: José Alejandro Arcila | F10: 2023 | G10: Miraflores | H10: Medellín | J10: no | K10: 0 | L10: 0 | M10: 400 | N10: 600 | P10: dc | Q10: 682 BTU/hour | Y10: Tarjeta 2*100G
A11: MPLS | B11: MPLS | C11: INCOME | D11: Cloud IP/MPLS | E11: José Alejandro Arcila | F11: 2023 | G11: Sabaneta | H11: Medellín | J11: no | K11: 0 | L11: 0 | M11: 400 | N11: 600 | P11: dc | Q11: 682 BTU/hour | Y11: Tarjeta 2*100G
A12: MPLS | B12: MPLS | C12: INCOME | D12: Cloud IP/MPLS | E12: José Alejandro Arcila | F12: 2023 | G12: Colón | H12: Medellín | J12: no | K12: 0 | L12: 0 | M12: 400 | N12: 600 | P12: dc | Q12: 682 BTU/hour | Y12: Tarjeta 2*100G
A13: MPLS | B13: MPLS | C13: INCOME | D13: Cloud IP/MPLS | E13: José Alejandro Arcila | F13: 2023 | G13: Miraflores | H13: Medellín | J13: no | K13: 0 | L13: 0 | M13: 400 | N13: 600 | P13: dc | Q13: 682 BTU/hour | Y13: Tarjeta 2*100G
... A16: MPLS | B16: MPLS | C16: INCOME | D16: Cloud IP/MPLS | E16: José Alejandro Arcila | F16: 2023 | G16: Gama | H16: Pereira | J16: no | K16: 0 | L16: 0 | M16: 400 | N16: 600 | P16: dc | Q16: 682 BTU/hour | Y16: Tarjeta 2*100G
A17: MPLS | B17: MPLS | C17: INCOME | D17: Cloud IP/MPLS | E17: José Alejandro Arcila | F17: 2023 | G17: Castilla | H17: Medellín | J17: si | K17: 1 | L17: 0 | M17: 400 | N17: 600 | P17: dc | Q17: 992 BTU/hour | R17: 2 | Y17: Swiche DAAS
A18: MPLS | B18: MPLS | C18: INCOME | D18: Cloud IP/MPLS | E18: José Alejandro Arcila | F18: 2023 | G18: Florencia | H18: Medellín | J18: si | K18: 1 | L18: 0 | M18: 400 | N18: 600 | P18: dc | Q18: 992 BTU/hour | R18: 2 | Y18: Swiche DAAS
A19: MPLS | B19: MPLS | C19: INCOME | D19: Cloud IP/MPLS | E19: José Alejandro Arcila | F19: 2023 | G19: Copacabana | H19: Medellín | J19: si | K19: 1 | L19: 0 | M19: 400 | N19: 600 | P19: dc | Q19: 992 BTU/hour | R19: 2 | Y19: Swiche DAAS
A20: MPLS | B20: MPLS | C20: INCOME | D20: Cloud IP/MPLS | E20: José Alejandro Arcila | F20: 2023 | G20: Colón | H20: Medellín | J20: si | K20: 1 | L20: 0 | M20: 400 | N20: 600 | P20: dc | Q20: 992 BTU/hour | R20: 2 | Y20: Swiche DAAS
A21: MPLS | B21: MPLS | C21: INCOME | D21: Cloud IP/MPLS | E21: José Alejandro Arcila | F21: 2023 | G21: Estrella | H21: Medellín | J21: si | K21: 1 | L21: 0 | M21: 400 | N21: 600 | P21: dc | Q21: 992 BTU/hour | R21: 2 | Y21: Swiche DAAS
A22: MPLS | B22: MPLS | C22: INCOME | D22: Cloud IP/MPLS | E22: José Alejandro Arcila | F22: 2023 | G22: Otrabanda | H22: Medellín | J22: si | K22: 1 | L22: 0 | M22: 400 | N22: 600 | P22: dc | Q22: 992 BTU/hour | R22: 2 | Y22: Swiche DAAS
A23: MPLS | B23: MPLS | C23: INCOME | D23: Cloud IP/MPLS | E23: José Alejandro Arcila | F23: 2023 | G23: San Cristóbal | H23: Medellín | J23: si | K23: 1 | L23: 0 | M23: 400 | N23: 600 | P23: dc | Q23: 992 BTU/hour | R23: 2 | Y23: Swiche DAAS
A24: MPLS | B24: MPLS | C24: INCOME | D24: Cloud IP/MPLS | E24: José Alejandro Arcila | F24: 2023 | G24: Villa hermosa | H24: Medellín | J24: si | K24: 1 | L24: 0 | M24: 400 | N24: 600 | P24: dc | Q24: 992 BTU/hour | R24: 2 | Y24: Swiche DAAS
A25: MPLS | B25: MPLS | C25: INCOME | D25: Cloud IP/MPLS | E25: José Alejandro Arcila | F25: 2023 | G25: La ceja | H25: Medellín | J25: si | K25: 1 | L25: 0 | M25: 400 | N25: 600 | P25: dc | Q25: 992 BTU/hour | R25: 2 | Y25: Swiche DAAS
A26: MPLS | B26: MPLS | C26: INCOME | D26: Cloud IP/MPLS | E26: José Alejandro Arcila | F26: 2023 | G26: Girardota | H26: Medellín | J26: si | K26: 1 | L26: 0 | M26: 400 | N26: 600 | P26: dc | Q26: 992 BTU/hour | R26: 2 | Y26: Swiche DAAS
A27: MPLS | B27: MPLS | C27: INCOME | D27: Cloud IP/MPLS | E27: José Alejandro Arcila | F27: 2023 | G27: Nodo Nuevo | H27: Santa Marha | J27: si | K27: 1 | L27: 0 | M27: 400 | N27: 600 | P27: dc | Q27: 992 BTU/hour | R27: 2 | Y27: Swiche DAAS
A28: MPLS | B28: MPLS | C28: INCOME | D28: Cloud IP/MPLS | E28: José Alejandro Arcila | F28: 2023 | G28: La Paz | H28: Bogotá | J28: si | K28: 1 | L28: 0 | M28: 400 | N28: 600 | P28: dc | Q28: 992 BTU/hour | R28: 2 | Y28: Swiche DAAS
... A36: MPLS | B36: MPLS | C36: INCOME | D36: Cloud IP/MPLS | E36: José Alejandro Arcila | F36: 2023 | G36: Centro | H36: Manizales | J36: si | K36: 1 | L36: 0 | M36: 400 | N36: 600 | P36: dc | Q36: 992 BTU/hour | R36: 2 | Y36: Swiche DAAS
A37: MPLS | B37: MPLS | C37: INCOME | D37: Cloud IP/MPLS | E37: José Alejandro Arcila | F37: 2023 | G37: San Cristóbal | H37: Medellín | J37: no | K37: 0 | L37: 0 | M37: 400 | N37: 600 | P37: dc | Q37: 682 BTU/hour | Y37: Tarjeta 12*10G
A38: MPLS | B38: MPLS | C38: INCOME | D38: Cloud IP/MPLS | E38: José Alejandro Arcila | F38: 2023 | G38: Santa Helena | H38: Medellín | J38: no | K38: 0 | L38: 0 | M38: 400 | N38: 600 | P38: dc | Q38: 682 BTU/hour | Y38: Tarjeta 12*10G
A39: MPLS | B39: MPLS | C39: INCOME | D39: Cloud IP/MPLS | E39: José Alejandro Arcila | F39: 2023 | G39: La Fe | H39: Medellín | J39: no | K39: 0 | L39: 0 | M39: 400 | N39: 600 | P39: dc | Q39: 682 BTU/hour | Y39: Tarjeta 12*10G
A40: MPLS | B40: MPLS | C40: INCOME | D40: Cloud IP/MPLS | E40: José Alejandro Arcila | F40: 2023 | G40: San Francisco | H40: Bucaramanga | J40: no | K40: 0 | L40: 0 | M40: 400 | N40: 600 | P40: dc | Q40: 682 BTU/hour | Y40: Tarjeta 12*10G
A41: MPLS | B41: MPLS | C41: INCOME | D41: Cloud IP/MPLS | E41: José Alejandro Arcila | F41: 2023 | G41: Chinchiná | H41: Caldas | J41: no | K41: 0 | L41: 0 | M41: 400 | N41: 600 | P41: dc | Q41: 682 BTU/hour | Y41: Tarjeta 12*10G
A42: MPLS | B42: MPLS | C42: INCOME | D42: Cloud IP/MPLS | E42: José Alejandro Arcila | F42: 2023 | G42: Miraflores | H42: Medellín | J42: no | K42: 0 | L42: 0 | M42: 400 | N42: 600 | P42: dc | Q42: 682 BTU/hour | Y42: Tarjeta 12*10G
A43: MPLS | B43: MPLS | C43: INCOME | D43: Cloud IP/MPLS | E43: José Alejandro Arcila | F43: 2023 | G43: Engativá | H43: Bogotá | J43: no | K43: 0 | L43: 0 | M43: 400 | N43: 600 | P43: dc | Q43: 682 BTU/hour | Y43: Tarjeta 12*10G
A44: MPLS | B44: MPLS | C44: INCOME | D44: Cloud IP/MPLS | E44: José Alejandro Arcila | F44: 2023 | G44: Centro ejecutivo | H44: Santa marta | J44: no | K44: 0 | L44: 0 | M44: 400 | N44: 600 | P44: dc | Q44: 682 BTU/hour | Y44: Tarjeta 12*10G
A45: MPLS | B45: MPLS | C45: INCOME | D45: Cloud IP/MPLS | E45: José Alejandro Arcila | F45: 2023 | G45: Valledupar | H45: Valledupar | J45: no | K45: 0 | L45: 0 | M45: 400 | N45: 600 | P45: dc | Q45: 682 BTU/hour | Y45: Tarjeta 12*10G
A46: MPLS | B46: MPLS | C46: INCOME | D46: Cloud IP/MPLS | E46: José Alejandro Arcila | F46: 2023 | G46: Montería | H46: Montería | J46: no | K46: 0 | L46: 0 | M46: 400 | N46: 600 | P46: dc | Q46: 682 BTU/hour | Y46: Tarjeta 12*10G
A47: MPLS | B47: MPLS | C47: INCOME | D47: Cloud IP/MPLS | E47: José Alejandro Arcila | F47: 2023 | G47: Buenos aires | H47: Medellín | J47: no | K47: 0 | L47: 0 | M47: 400 | N47: 600 | P47: dc | Q47: 682 BTU/hour | Y47: Tarjeta 12*10G
A48: MPLS | B48: MPLS | C48: INCOME | D48: Cloud IP/MPLS | E48: José Alejandro Arcila | F48: 2023 | G48: Itagüí | H48: Medellín | J48: no | K48: 0 | L48: 0 | M48: 400 | N48: 600 | P48: dc | Q48: 682 BTU/hour | Y48: Tarjeta 12*10G
... A69: MPLS | B69: MPLS | C69: INCOME | D69: Cloud IP/MPLS | E69: José Alejandro Arcila | F69: 2023 | G69: Carrera | H69: Bogotá | J69: yes | K69: 2 | L69: 2 | M69: 3800 | N69: 4100 | P69: dc | Q69: 13290 BTU/hour | Y69: Router 7750
...

Sheet IAP
A1: Platform or Equipment | B1: Associated Services to the platform | C1: Income / Dismount | D1: Responsable Technical Area | E1: Responsable Technician | F1: Year | G1: Technical Site | H1: City | I1: Regional | J1: Additional m2? Yes/No | K1: If Yes: # Racks? | L1: Quantity Equipment DC | M1: Average Power (W) | N1: Máx. Power DC (W) | O1: Potencia liberar | P1: Voltage (AC or DC) | Q1: Air DissipationBTU | R1: Power sources | S1: Quantity Equipment AC | T1: Máx. Power AC (W) | U1: Voltage (AC or DC) | V1: Requested Area (M2) | W1: Instalation date | X1: Prority | Y1: Comments
A2: IAP | B2: Internet, datos, voz, B2B, TV | C2: Income | D2: Gerencia Cloud, IP y DC | E2: Sandra Prieto | F2: 2023 | G2: Montevideo | H2: Bogotá | J2: Yes | K2: 1 | M2: 6802.5 | N2: 9070 | P2: DC | Q2: 23210.81 | R2: 2 | T2: 48 VDC | U2: DC | W2: 45078 | Y2: 1 rack y equipo MX10k8 nuevo (PDU en rack 26kw)
A3: IAP | B3: Internet, datos, voz, B2B, TV | C3: Income | D3: Gerencia Cloud, IP y DC | E3: Sandra Prieto | F3: 2023 | G3: Miraflores | H3: Medellín | J3: No | M3: 1327.5 | N3: 1770 | P3: DC | Q3: 4529.56 | T3: 48 VDC | U3: DC | W3: 45078 | Y3: Tarjetas en router MX960/10k8 existente
A4: IAP | B4: Internet, datos, voz, B2B, TV | C4: Income | D4: Gerencia Cloud, IP y DC | E4: Sandra Prieto | F4: 2023 | G4: Bosque | H4: Cartagena | J4: No | M4: 1327.5 | N4: 1770 | P4: DC | Q4: 4529.56 | T4: 48 VDC | U4: DC | W4: 45078 | Y4: Tarjetas en router MX960/10k8 existente
A5: IAP | B5: Internet, datos, voz, B2B, TV | C5: Income | D5: Gerencia Cloud, IP y DC | E5: Sandra Prieto | F5: 2023 | G5: Anillo Vial | H5: Bucaramanga | J5: No | M5: 1177.5 | N5: 1570 | P5: DC | Q5: 4017.75 | T5: 48 VDC | U5: DC | W5: 45078 | Y5: Tarjetas en router MX960/10k8 existente
A6: IAP | B6: Internet, datos, voz, B2B, TV | C6: Income | D6: Gerencia Cloud, IP y DC | E6: Sandra Prieto | F6: 2023 | G6: Centro | H6: Manizales | J6: No | M6: 1177.5 | N6: 1570 | P6: DC | Q6: 4017.75 | T6: 48 VDC | U6: DC | W6: 45078 | Y6: Tarjetas en router MX960/10k8 existente
A7: IAP | B7: Internet, datos, voz, B2B, TV | C7: Income | D7: Gerencia Cloud, IP y DC | E7: Sandra Prieto | F7: 2023 | G7: Alamos | H7: Pereira | J7: No | M7: 1177.5 | N7: 1570 | P7: DC | Q7: 4017.75 | T7: 48 VDC | U7: DC | W7: 45078 | Y7: Tarjetas en router MX960/10k8 existente
A8: IAP | B8: Internet, datos, voz, B2B, TV | C8: Income | D8: Gerencia Cloud, IP y DC | E8: Sandra Prieto | F8: 2023 | G8: Centro | H8: Pereira | J8: No | M8: 1177.5 | N8: 1570 | P8: DC | Q8: 4017.75 | T8: 48 VDC | U8: DC | W8: 45078 | Y8: Tarjetas en router MX960/10k8 existente
A9: IAP | B9: Internet, datos, voz, B2B, TV | C9: Income | D9: Gerencia Cloud, IP y DC | E9: Sandra Prieto | F9: 2023 | G9: Vasquez Cobo | H9: Cali | J9: No | M9: 2355 | N9: 3140 | P9: DC | Q9: 8035.5 | T9: 48 VDC | U9: DC | W9: 45078 | Y9: Tarjetas en router MX960/10k8 existente
A10: IAP | B10: Internet | C10: INCOME | D10: Cloud IP Data Center | E10: Alex Orrego | F10: 2023 | G10: Bosque | H10: Cartagena | J10: yes | K10: 1 | M10: 4500 | N10: 5000 | P10: DC | Q10: 24000 | R10: 2 | T10: 48 VDC | U10: DC | W10: 45078 | Y10: CDNs
A11: IAP | B11: Internet | C11: INCOME | D11: Cloud IP Data Center | E11: Alex Orrego | F11: 2023 | G11: Host | H11: Monteria | J11: yes | K11: 1 | M11: 4500 | N11: 5000 | P11: DC | Q11: 24000 | R11: 2 | T11: 48 VDC | U11: DC | W11: 45078 | Y11: CDNs
A12: IAP | B12: Internet | C12: INCOME | D12: Cloud IP Data Center | E12: Alex Orrego | F12: 2023 | G12: Vasquez cobo | H12: Cali | J12: yes | K12: 1 | M12: 4500 | N12: 5000 | P12: DC | Q12: 24000 | R12: 2 | T12: 48 VDC | U12: DC | W12: 45078 | Y12: CDNs
A13: IAP | B13: Internet | C13: INCOME | D13: Cloud IP Data Center | E13: Alex Orrego | F13: 2023 | G13: Anillo vial | H13: Bucaramanga | J13: yes | K13: 1 | M13: 4500 | N13: 5000 | P13: DC | Q13: 24000 | R13: 2 | T13: 48 VDC | U13: DC | W13: 45078 | Y13: CDNs
A14: IAP | B14: Internet | C14: INCOME | D14: Cloud IP Data Center | E14: Alex Orrego | F14: 2023 | G14: Centro | H14: Manizales | J14: yes | K14: 1 | M14: 4500 | N14: 5000 | P14: DC | Q14: 24000 | R14: 2 | T14: 48 VDC | U14: DC | W14: 45078 | Y14: CDNs
A15: IAP | B15: Internet | C15: INCOME | D15: Cloud IP Data Center | E15: Alex Orrego | F15: 2023 | G15: Centro | H15: Pereira | J15: yes | K15: 1 | M15: 4500 | N15: 5000 | P15: DC | Q15: 33600 | R15: 2 | T15: 48 VDC | U15: DC | W15: 45078 | Y15: CDNs
A16: IAP | B16: Internet | C16: INCOME | D16: Cloud IP Data Center | E16: Alex Orrego | F16: 2023 | G16: Alamos | H16: Pereira | J16: yes | K16: 1 | M16: 4500 | N16: 5000 | P16: DC | Q16: 33600 | R16: 2 | T16: 48 VDC | U16: DC | W16: 45078 | Y16: CDNs

Sheet Hoja2
A1: Equipment | B1: Income / Dismount | C1: Technical Site | D1: Additional m2? Yes/No | E1: If Yes: # Racks? | F1: Tipo de racks | G1: Quantity Equipment DC | H1: Average Power (W) | I1: Máx. Power DC (W) | J1: Es ampliación de tarjeta en equipo existente? | K1: Potencia a liberar | L1: Sitio y equipo con el que se libero la potencia | M1: Voltage (AC or DC) | N1: Air DissipationBTU | O1: Power sources | P1: PRE-Factibilidad Infraestructura (Si / No)

Sheet BU FACILITIES
D1: TRM | G1: 4100
A3: Descripción | B3: Capacidad | C3: Cantidad | D3: Valor Suministro | E3: Valor Inst | F3: Valor acometidas | G3: Valor Total
A4: Rectificador | B4: 300 | C4: 1 | D4: 6132 | E4: 352.43902 | F4: 4878.0488 | G4: 11362.488 | AS4: =IF(AR4=300,AQ4*'BU FACILITIES'!$G$4, IF(AND(AR4>=300,AR4<500), AQ4*#REF!, IF(AND(AR4>=500,AR4<1250), AQ4*#REF!, IF(AND(AR4>=1250,AR4<2000),AQ4*#REF!, IF(AR4>=2000,AQ4*#REF!, "")))))
A5: Rectificador | B5: 500 | C5: 1 | D5: 7227 | E5: 352.43902 | F5: 4878.0488 | G5: 12457.488
A6: Rectificador | B6: 1250 | C6: 1 | D6: 13352 | E6: 352.43902 | F6: 4878.0488 | G6: 18582.488
A7: Rectificador | B7: 2000 | C7: 1 | D7: 18632 | E7: 352.43902 | F7: 4878.0488 | G7: 23862.488
A8: Baterías | B8: 100 | C8: 1 | D8: 1230 | E8: 975.60976 | F8: 121.95122 | G8: 2327.561
A9: Baterías | B9: 500 | C9: 1 | D9: 4517.1487 | E9: 975.60976 | F9: 3658.5366 | G9: 9151.2951
A10: Baterías | B10: 800 | C10: 1 | D10: 10064.295 | E10: 975.60976 | F10: 3658.5366 | G10: 14698.441
A11: Baterías | B11: 1000 | C11: 1 | D11: 8197.7641 | E11: 975.60976 | F11: 3658.5366 | G11: 12831.91
A12: Baterías | B12: 1400 | C12: 1 | D12: 18807.5 | E12: 975.60976 | F12: 3658.5366 | G12: 23441.646
A13: Baterías | B13: 2000 | C13: 1 | D13: 16817.86 | E13: 975.60976 | F13: 3658.5366 | G13: 21452.006
A14: Motogenerador | B14: 45 | C14: 1 | D14: 8806 | E14: 9756.0976 | F14: 0 | G14: 18562.098
A15: Motogenerador | B15: 30 | C15: 1 | D15: 8020 | E15: 9756.0976 | F15: 0 | G15: 17776.098
A16: Motogenerador | B16: 450 | C16: 1 | G16: 75800.829
A17: Equipos de AA | B17: 5 | C17: 1 | D17: 5400 | E17: 8126.8293 | F17: 0 | G17: 13526.829
A18: Equipos de AA | B18: 10 | C18: 1 | D18: 6400 | E18: 8126.8293 | F18: 0 | G18: 14526.829
A19: Equipos de AA | B19: 20 | C19: 1 | D19: 14500 | E19: 8126.8293 | F19: 0 | G19: 22626.829
A20: Rediseño ductos de AA | C20: 1 | D20: 9756.0976 | E20: 0 | F20: 0 | G20: 9756.0976
A21: Tablero PDB | C21: 1 | D21: 1714.6341 | F21: 0 | G21: =+F21+D21 -> 1714.6341
A22: Energización equipos | C22: 1 | D22: 870.73171 | G22: 870.73171
A23: Obra civil | C23: 1 | D23: 24390.244 | G23: 24390.244
A24: Obra electrica complementaria | C24: 1 | D24: 9756.0976 | G24: 9756.0976
D25: TOTAL | G25: =SUM(G4:G24) -> 359475.13

Sheet Prefactibilidad negativa
A1: Platform or Equipment | B1: Associated Services to the platform | C1: Income / Dismount | D1: Responsable Technical Area | E1: Responsable Technician | F1: Year | G1: Technical Site | H1: City | I1: Regional | J1: Additional m2? Yes/No | K1: If Yes: # Racks? | L1: Quantity Equipment DC | M1: Average Power (W) | N1: Máx. Power DC (W) | O1: Potencia liberar | P1: Sumatoria W | Q1: %Potencia | R1: Valor por porcentaje de potencia | S1: Voltage (AC or DC) | T1: Air DissipationBTU | U1: Power sources | V1: Quantity Equipment AC | W1: Máx. Power AC (W) | X1: Voltage (AC or DC) | Y1: Requested Area (M2) | Z1: Instalation date | AA1: Prority | AB1: Comments | AC1: OBSERVACIÓN GERENCIA INFRAESTRUCTURA | AD1: tipo de NODO | AE1: PRE-Factibilidad Infraestructura (Si / No)
A2: Plataforma OLT Equipo Nuevo | B2: BBI-TV-TOIP | C2: Income | D2: Gerencia Acceso Fijo | E2: Henry Campos | F2: 2023 | G2: Jamundi | H2: Jamundí | J2: Yes | K2: 2 | L2: 1 | M2: 842 | N2: 1403 | P2: =SUMIF($G$3:$G$360,G2,$N$3:$N$360) -> 4209 | Q2: =N2/P2 -> 0.33333333 | R2: =VLOOKUP(G2,#REF!,11,0)*Q2 -> #REF! | S2: DC | U2: 2 | V2: 0 | W2: 0 | X2: DC | Y2: 3 | Z2: Q2 | AC2: El sitio no cuenta con espacio, ni AA ni rectificador para soportar la carga, debe construirse un sitio nuevo ya que el actual no tiene forma de expandirse. Se revisó sitios propios en Jamundí para revisar posibilidad de instalar OLT intemperie y el sitio que más se ajusta a las necesiddes de la zona requiere adecuaciones por aproximadamente 45 millones para volverlo confiable para la instalación de una OLT intemperie. | AD2: 5 | AE2: NO
A3: Plataforma OLT Equipo Nuevo | B3: BBI-TV-TOIP | C3: Income | D3: Gerencia Acceso Fijo | E3: Henry Campos | F3: 2023 | G3: Nuevo Nodo (Reemplzao ECE) | H3: Santa Marta | J3: Yes | K3: 2 | L3: 1 | M3: 842 | N3: 1403 | P3: =SUMIF($G$3:$G$360,G3,$N$3:$N$360) -> 7340 | Q3: =N3/P3 -> 0.19114441 | R3: =VLOOKUP(G3,#REF!,11,0)*Q3 -> #REF! | S3: DC | U3: 2 | V3: 0 | W3: 0 | X3: DC | Y3: 3 | Z3: Q2 | AB3: OLT nueva | AC3: Sitio por conseguir | AE3: NO
A4: Plataforma OLT Equipo Nuevo | B4: BBI-TV-TOIP | C4: Income | D4: Gerencia Acceso Fijo | E4: Henry Campos | F4: 2023 | G4: Chinchiná | H4: Chinchiná | J4: Yes | K4: 2 | L4: 1 | M4: 842 | N4: 1403 | P4: =SUMIF($G$3:$G$360,G4,$N$3:$N$360) -> 2806 | Q4: =N4/P4 -> 0.5 | R4: =VLOOKUP(G4,#REF!,11,0)*Q4 -> #REF! | S4: DC | U4: 2 | V4: 0 | W4: 0 | X4: DC | Y4: 3 | Z4: Q3 | AB4: OLT nueva | AC4: Sitio sin espacio, requiere obra civil. (35 millones aprox). Se debe negociar con la estación de Policia. | AD4: Urbano | AE4: No
A5: Plataforma OLT Equipo Nuevo | B5: BBI-TV-TOIP | C5: Income | D5: Gerencia Acceso Fijo | E5: Henry Campos | F5: 2023 | G5: Puerto Colombia | H5: Puerto Colombia | J5: Yes | K5: 2 | L5: 1 | M5: 842 | N5: 1403 | P5: =SUMIF($G$3:$G$360,G5,$N$3:$N$360) -> 2806 | Q5: =N5/P5 -> 0.5 | R5: =VLOOKUP(G5,#REF!,11,0)*Q5 -> #REF! | S5: DC | U5: 2 | V5: 0 | W5: 0 | X5: DC | Y5: 3 | Z5: Q3 | AB5: OLT nueva | AC5: Se buscará mejor sitio por seguridad, sitios movil han sido vandalizados | AE5: NO
A6: Plataforma OLT Equipo Nuevo | B6: BBI-TV-TOIP | C6: Income | D6: Gerencia Acceso Fijo | E6: Henry Campos | F6: 2023 | G6: Jamundi | H6: Jamundí | J6: Yes | K6: 2 | L6: 1 | M6: 842 | N6: 1403 | P6: =SUMIF($G$3:$G$360,G6,$N$3:$N$360) -> 4209 | Q6: =N6/P6 -> 0.33333333 | R6: =VLOOKUP(G6,#REF!,11,0)*Q6 -> #REF! | S6: DC | U6: 2 | V6: 0 | W6: 0 | X6: DC | Y6: 3 | Z6: Q2 | AB6: OLT nueva | AC6: No se tiene esapcio ni capacidad en rectificadores y AA | AD6: 5 | AE6: NO
A7: Plataforma RemotePhy Equipo Nuevo | B7: BBI-TV-TOIP | C7: Income | D7: Gerencia Acceso Fijo | E7: Jorge Mauricio | F7: 2023 | G7: Nuevo Nodo (Reemplzao ECE) | H7: Santa Marta | J7: Yes | K7: 1 | L7: 4 | M7: 2267 | N7: 2267 | P7: =SUMIF($G$3:$G$360,G7,$N$3:$N$360) -> 7340 | Q7: =N7/P7 -> 0.30885559 | R7: =VLOOKUP(G7,#REF!,11,0)*Q7 -> #REF! | S7: DC | U7: 8 | V7: 0 | W7: 0 | X7: DC | Y7: 1.5 | Z7: Q2 | AC7: Por conseguir el sitio | AE7: NO
A8: Plataforma Óptica | B8: BBI-TV-TOIP | C8: Income | D8: Gerencia Acceso Fijo | E8: Jorge Ivan Pérez Cardona | F8: 2023 | G8: La Paz (Bosa) | H8: Bogotá | J8: Yes | K8: 1 | L8: 6 | M8: 475 | N8: 2850 | P8: =SUMIF($G$3:$G$360,G8,$N$3:$N$360) -> 5700 | Q8: =N8/P8 -> 0.5 | R8: =VLOOKUP(G8,#REF!,11,0)*Q8 -> #REF! | S8: DC | T8: 1620.75 | U8: 2 | X8: 48 VDC | Y8: 1.5 | Z8: Q1-Q2 | AB8: Transmisores y Receptotes Ópticos | AC8: No se tiene capacidad AC. Se debe realizar proyecto de aumento de capacidad con CODENSA | AE8: NO
A9: Plataforma Óptica | B9: BBI-TV-TOIP | C9: Income | D9: Gerencia Acceso Fijo | E9: Jorge Ivan Pérez Cardona | F9: 2023 | G9: Linda Vista | H9: Barranquilla | J9: Yes | K9: 1 | L9: 2 | M9: 475 | N9: 950 | P9: =SUMIF($G$3:$G$360,G9,$N$3:$N$360) -> 1900 | Q9: =N9/P9 -> 0.5 | R9: =VLOOKUP(G9,#REF!,11,0)*Q9 -> #REF! | S9: DC | T9: 1620.75 | U9: 2 | X9: 48 VDC | Y9: 1.5 | Z9: Q1-Q2 | AB9: Transmisores y Receptotes Ópticos | AC9: Este nodo está en proceso de desmonte | AD9: 5 | AE9: NO
A10: Plataforma Óptica | B10: BBI-TV-TOIP | C10: Income | D10: Gerencia Acceso Fijo | E10: Jorge Ivan Pérez Cardona | F10: 2023 | G10: Centro Ejecutivo | H10: Santa Marta | J10: Yes | K10: 1 | L10: 6 | M10: 475 | N10: 2850 | P10: =SUMIF($G$3:$G$360,G10,$N$3:$N$360) -> 8100 | Q10: =N10/P10 -> 0.35185185 | R10: =VLOOKUP(G10,#REF!,11,0)*Q10 -> #REF! | S10: DC | T10: 1620.75 | U10: 2 | X10: 48 VDC | Y10: 1.5 | Z10: Q1-Q2 | AB10: Transmisores y Receptotes Ópticos | AC10: Sitio sobrecargado energía y refrigeración | AD10: 4 | AE10: NO
A11: Plataforma Óptica | B11: BBI-TV-TOIP | C11: Income | D11: Gerencia Acceso Fijo | E11: Jorge Ivan Pérez Cardona | F11: 2023 | G11: Camara de Comercio | H11: Armenia | K11: 1 | L11: 6 | M11: 475 | N11: 2850 | P11: =SUMIF($G$3:$G$360,G11,$N$3:$N$360) -> 5700 | Q11: =N11/P11 -> 0.5 | R11: =VLOOKUP(G11,#REF!,11,0)*Q11 -> #REF! | S11: DC | T11: 1620.75 | U11: 2 | X11: 48 VDC | Y11: 1.5 | Z11: Q1-Q2 | AB11: Transmisores y Receptotes Ópticos | AC11: Sitio sin espacio. No hay forma de ampliación. | AD11: 4 | AE11: No
A12: Plataforma Óptica | B12: BBI-TV-TOIP | C12: Income | D12: Gerencia Acceso Fijo | E12: Jorge Ivan Pérez Cardona | F12: 2023 | G12: Cabecera | H12: Armenia | J12: Yes | K12: 1 | L12: 6 | M12: 475 | N12: 2850 | P12: =SUMIF($G$3:$G$360,G12,$N$3:$N$360) -> 2850 | Q12: =N12/P12 -> 1 | R12: =VLOOKUP(G12,#REF!,11,0)*Q12 -> #REF! | S12: DC | T12: 1620.75 | U12: 2 | X12: 48 VDC | Y12: 1.5 | Z12: Q1-Q2 | AB12: Transmisores y Receptotes Ópticos | AC12: Sitio sin espacio. No hay forma de ampliación. | AD12: 4 | AE12: No
A13: MPLS | B13: MPLS | C13: INCOME | D13: Gerencia Cloud, IP y DC | E13: José Alejandro Arcila | F13: 2023 | G13: Centro ejecutivo | H13: Santa Marta | J13: no | K13: 0 | L13: 0 | M13: 400 | N13: 600 | P13: =SUMIF($G$3:$G$360,G13,$N$3:$N$360) -> 8100 | Q13: =N13/P13 -> 0.074074074 | R13: =VLOOKUP(G13,#REF!,11,0)*Q13 -> #REF! | S13: dc | T13: 682 BTU/hour | AB13: Tarjeta 24*10 | AC13: Sitio sobrecargado energía y refrigeración | AD13: 4 | AE13: NO
A14: MPLS | B14: MPLS | C14: INCOME | D14: Gerencia Cloud, IP y DC | E14: José Alejandro Arcila | F14: 2023 | G14: Nodo Nuevo | H14: Santa Marta | J14: si | K14: 1 | L14: 0 | M14: 400 | N14: 600 | P14: =SUMIF($G$3:$G$360,G14,$N$3:$N$360) -> 2400 | Q14: =N14/P14 -> 0.25 | R14: =VLOOKUP(G14,#REF!,11,0)*Q14 -> #REF! | S14: dc | T14: 992 BTU/hour | U14: 2 | AB14: Swiche DAAS | AC14: Por conseguir el sitio | AE14: NO
A15: MPLS | B15: MPLS | C15: INCOME | D15: Gerencia Cloud, IP y DC | E15: José Alejandro Arcila | F15: 2023 | G15: La Paz | H15: Bogotá | J15: si | K15: 1 | L15: 0 | M15: 400 | N15: 600 | P15: =SUMIF($G$3:$G$360,G15,$N$3:$N$360) -> 3600 | Q15: =N15/P15 -> 0.16666667 | R15: =VLOOKUP(G15,#REF!,11,0)*Q15 -> #REF! | S15: dc | T15: 992 BTU/hour | U15: 2 | AB15: Swiche DAAS | AC15: No se tiene capacidad AC. Se debe realizar proyecto de aumento de capacidad con CODENSA | AE15: NO
A16: MPLS | B16: MPLS | C16: INCOME | D16: Gerencia Cloud, IP y DC | E16: José Alejandro Arcila | F16: 2023 | G16: Quinta Camacho | H16: Cúcuta | J16: si | K16: 1 | L16: 0 | M16: 400 | N16: 600 | P16: =SUMIF($G$3:$G$360,G16,$N$3:$N$360) -> 2400 | Q16: =N16/P16 -> 0.25 | R16: =VLOOKUP(G16,#REF!,11,0)*Q16 -> #REF! | S16: dc | T16: 992 BTU/hour | U16: 2 | AB16: Swiche DAAS | AC16: No se tiene un nodo con el nombre Quinta Camacho en el gobierno de Facilities para Cucuta | AE16: NO
A17: MPLS | B17: MPLS | C17: INCOME | D17: Gerencia Cloud, IP y DC | E17: José Alejandro Arcila | F17: 2023 | G17: Centro ejecutivo | H17: Santa Marta | J17: no | K17: 0 | L17: 0 | M17: 400 | N17: 600 | P17: =SUMIF($G$3:$G$360,G17,$N$3:$N$360) -> 8100 | Q17: =N17/P17 -> 0.074074074 | R17: =VLOOKUP(G17,#REF!,11,0)*Q17 -> #REF! | S17: dc | T17: 682 BTU/hour | AB17: Tarjeta 12*10G | AC17: Sitio sobrecargado energía y refrigeración | AD17: 4 | AE17: NO
A18: MPLS | B18: MPLS | C18: INCOME | D18: Gerencia Cloud, IP y DC | E18: José Alejandro Arcila | F18: 2023 | G18: Nodo Nuevo | H18: Santa Marta | J18: no | K18: 0 | L18: 0 | M18: 400 | N18: 600 | P18: =SUMIF($G$3:$G$360,G18,$N$3:$N$360) -> 2400 | Q18: =N18/P18 -> 0.25 | R18: =VLOOKUP(G18,#REF!,11,0)*Q18 -> #REF! | S18: dc | T18: 682 BTU/hour | AB18: Tarjeta 12*10G | AC18: Sitio por conseguir | AE18: NO
A19: MPLS | B19: MPLS | C19: INCOME | D19: Gerencia Cloud, IP y DC | E19: José Alejandro Arcila | F19: 2023 | G19: La Paz | H19: Bogotá | J19: no | K19: 0 | L19: 0 | M19: 400 | N19: 600 | P19: =SUMIF($G$3:$G$360,G19,$N$3:$N$360) -> 3600 | Q19: =N19/P19 -> 0.16666667 | R19: =VLOOKUP(G19,#REF!,11,0)*Q19 -> #REF! | S19: dc | T19: 682 BTU/hour | AB19: Tarjeta 12*10G | AC19: No se tiene capacidad AC. Se debe realizar proyecto de aumento de capacidad con CODENSA | AE19: NO
A20: MPLS | B20: MPLS | C20: INCOME | D20: Gerencia Cloud, IP y DC | E20: José Alejandro Arcila | F20: 2023 | G20: Quinta Camacho | H20: Cúcuta | J20: no | K20: 0 | L20: 0 | M20: 400 | N20: 600 | P20: =SUMIF($G$3:$G$360,G20,$N$3:$N$360) -> 2400 | Q20: =N20/P20 -> 0.25 | R20: =VLOOKUP(G20,#REF!,11,0)*Q20 -> #REF! | S20: dc | T20: 682 BTU/hour | AB20: Tarjeta 12*10G | AC20: No se tiene un nodo con el nombre Quinta Camacho en el gobierno de Facilities para Cucuta | AE20: NO
A21: MPLS | B21: MPLS | C21: INCOME | D21: Gerencia Cloud, IP y DC | E21: José Alejandro Arcila | F21: 2023 | G21: Carrera | H21: Bogotá | J21: yes | K21: 2 | L21: 2 | M21: 3800 | N21: 4100 | P21: =SUMIF($G$3:$G$360,G21,$N$3:$N$360) -> 12200 | Q21: =N21/P21 -> 0.33606557 | R21: =VLOOKUP(G21,#REF!,11,0)*Q21 -> #REF! | S21: dc | T21: 13290 BTU/hour | AB21: Router 7750 | AC21: El nodo se migrará al sitios GALAN. Se debe solicitar el despliegue en este nuevo sitio. | AD21: N5 | AE21: NO
A22: MPLS | B22: MPLS | C22: Dismount | D22: Gerencia Cloud, IP y DC | E22: José Alejandro Arcila | F22: 2023 | G22: Carrera | H22: Bogotá | J22: no | L22: 2 | M22: 1500 | N22: 2000 | P22: =SUMIF($G$3:$G$360,G22,$N$3:$N$360) -> 12200 | Q22: =N22/P22 -> 0.16393443 | R22: =VLOOKUP(G22,#REF!,11,0)*Q22 -> #REF! | S22: dc | T22: 7000 BTU/hour | AB22: DEsmonte Sw9303 | AC22: El nodo se migrará al sitios GALAN. Se debe solicitar el despliegue en este nuevo sitio. | AD22: N5 | AE22: NO
A23: MPLS | B23: MPLS | C23: INCOME | D23: Gerencia Cloud, IP y DC | E23: José Alejandro Arcila | F23: 2023 | G23: BCC | H23: Bogotá | J23: yes | K23: 2 | L23: 2 | M23: 3800 | N23: 4100 | P23: =SUMIF($G$3:$G$360,G23,$N$3:$N$360) -> 4100 | Q23: =N23/P23 -> 1 | R23: =VLOOKUP(G23,#REF!,11,0)*Q23 -> #REF! | S23: dc | T23: 13290 BTU/hour | AB23: Router 7750 | AC23: No se cuenta con espacio disponibile para instalación de Rack, se debe validar en sitio si hay unidades de rack disponible para reutilizar. No se tiene disponibilidad en DC. Sitio Cerrado | AD23: N5 | AE23: NO
A24: MPLS | B24: MPLS | C24: INCOME | D24: Gerencia Cloud, IP y DC | E24: José Alejandro Arcila | F24: 2023 | G24: WTC (World Trade Center) | H24: Bogotá | J24: yes | K24: 2 | L24: 2 | M24: 3800 | N24: 4100 | P24: =SUMIF($G$3:$G$360,G24,$N$3:$N$360) -> 4100 | Q24: =N24/P24 -> 1 | R24: =VLOOKUP(G24,#REF!,11,0)*Q24 -> #REF! | S24: dc | T24: 13290 BTU/hour | AB24: Router 7750 | AC24: No se cuenta con espacio disponibile para instalación de Rack, se debe validar en sitio si hay unidades de rack disponible para reutilizar. No se tiene disponibilidad en DC. Sitio Cerrado | AD24: N5 | AE24: NO
A25: MPLS | B25: MPLS | C25: INCOME | D25: Gerencia Cloud, IP y DC | E25: José Alejandro Arcila | F25: 2023 | G25: La Paz | H25: Bogotá | J25: no | K25: 0 | L25: 0 | M25: 400 | N25: 600 | P25: =SUMIF($G$3:$G$360,G25,$N$3:$N$360) -> 3600 | Q25: =N25/P25 -> 0.16666667 | R25: =VLOOKUP(G25,#REF!,11,0)*Q25 -> #REF! | S25: dc | T25: 682 BTU/hour | AB25: Tarjeta 12*10G | AC25: No se tiene capacidad AC. Se debe realizar proyecto de aumento de capacidad con CODENSA | AE25: NO
A26: Plataforma Óptica | B26: BBI-TV-TOIP | C26: Income | D26: Gerencia Acceso Fijo | E26: Jorge Ivan Pérez Cardona | F26: 2023 | G26: La Florida | H26: Florida Blanca | J26: Yes | K26: 2 | L26: 4 | M26: 475 | N26: 1403 | P26: =SUMIF($G$3:$G$360,G26,$N$3:$N$360) -> 2806 | Q26: =N26/P26 -> 0.5 | R26: =VLOOKUP(G26,#REF!,11,0)*Q26 -> #REF! | S26: DC | T26: 1620.75 | U26: 4 | X26: 48 VDC | Y26: 3 | Z26: Q1-Q2 | AB26: Transmisores y Receptotes Ópticos | AC26: No se tiene espacio en Piso ni disponible para crecer. Esto se había dialogado en su momento cuando se instaló la OLT | AD26: N5 | AE26: NO
A27: MPLS | B27: MPLS | C27: INCOME | D27: Gerencia Cloud, IP y DC | E27: José Alejandro Arcila | F27: 2023 | G27: Cuestesitas | H27: Riohacha | J27: no | K27: 0 | L27: 0 | M27: 400 | N27: 600 | P27: =SUMIF($G$3:$G$360,G27,$N$3:$N$360) -> 1200 | Q27: =N27/P27 -> 0.5 | R27: =VLOOKUP(G27,#REF!,11,0)*Q27 -> #REF! | S27: dc | T27: 682 BTU/hour | AB27: 12*10G | AC27: Sitio Internexa, no hay datos Facilities | AE27: NO
A29: Plataforma OLT Equipo Nuevo | B29: BBI-TV-TOIP | C29: Income | D29: Gerencia Acceso Fijo | E29: Henry Campos | F29: 2023 | G29: Jamundi | H29: Jamundí | J29: Yes | K29: 2 | L29: 1 | M29: 842 | N29: 1403 | P29: =SUMIF($G$3:$G$316,G29,$N$3:$N$316) -> 4209 | Q29: =IF(N29<>0,N29/P29,"0") -> 0.33333333 | R29: =VLOOKUP(G29,#REF!,11,0)*Q29 -> #REF! | S29: DC | U29: 2 | V29: 0 | W29: 0 | X29: DC | Y29: 3 | Z29: Q2 | AC29: El sitio no cuenta con espacio, ni AA ni rectificador para soportar la carga, debe construirse un sitio nuevo ya que el actual no tiene forma de expandirse. Se revisó sitios propios en Jamundí para revisar posibilidad de instalar OLT intemperie y el sitio que más se ajusta a las necesiddes de la zona requiere adecuaciones por aproximadamente 45 millones para volverlo confiable para la instalación de una OLT intemperie. | AD29: 5 | AE29: NO | AF29: Sitio nuevo | AI29: Sitio nuevo | AK29: =AJ29*'BU FACILITIES'!$G$21 -> 0 | AL29: 0 | AM29: =PRODUCT( AL29,'BU FACILITIES'!$G$22) -> 0 | AN29: sitio nuevo | AP29: =IF(AO29=1,'BU FACILITIES'!$G$23,"") | AQ29: 0 | AR29: 1200 | AT29: 0 | AU29: 800 | AW29: 0 | AX29: 45 | AZ29: 0 | BA29: 5
A30: Plataforma OLT Equipo Nuevo | B30: BBI-TV-TOIP | C30: Income | D30: Gerencia Acceso Fijo | E30: Henry Campos | F30: 2023 | G30: Nuevo Nodo (Reemplzao ECE) | H30: Santa Marta | J30: Yes | K30: 2 | L30: 1 | M30: 842 | N30: 1403 | P30: =SUMIF($G$3:$G$316,G30,$N$3:$N$316) -> 7340 | Q30: =IF(N30<>0,N30/P30,"0") -> 0.19114441 | R30: =VLOOKUP(G30,#REF!,11,0)*Q30 -> #REF! | S30: DC | U30: 2 | V30: 0 | W30: 0 | X30: DC | Y30: 3 | Z30: Q2 | AB30: OLT nueva | AC30: Sitio por conseguir | AE30: NO | AF30: No | AI30: No | AK30: =AJ30*'BU FACILITIES'!$G$21 -> 0 | AL30: 0 | AM30: =PRODUCT( AL30,'BU FACILITIES'!$G$22) -> 0 | AN30: No | AP30: =IF(AO30=1,'BU FACILITIES'!$G$23,"") | AQ30: =2*0 -> 0 | AR30: =300*0 -> 0 | AT30: =8*0 -> 0 | AU30: =100*0 -> 0 | AW30: =1*0 -> 0 | AX30: =30*0 -> 0 | AZ30: =2*0 -> 0 | BA30: =3*0 -> 0
A31: Plataforma OLT Equipo Nuevo | B31: BBI-TV-TOIP | C31: Income | D31: Gerencia Acceso Fijo | E31: Henry Campos | F31: 2023 | G31: Chinchiná | H31: Chinchiná | J31: Yes | K31: 2 | L31: 1 | M31: 842 | N31: 1403 | P31: =SUMIF($G$3:$G$316,G31,$N$3:$N$316) -> 2806 | Q31: =IF(N31<>0,N31/P31,"0") -> 0.5 | R31: =VLOOKUP(G31,#REF!,11,0)*Q31 -> #REF! | S31: DC | U31: 2 | V31: 0 | W31: 0 | X31: DC | Y31: 3 | Z31: Q3 | AB31: OLT nueva | AC31: Sitio sin espacio, requiere obra civil. (35 millones aprox). Se debe negociar con la estación de Policia. | AD31: Urbano | AE31: No | AI31: PDB | AJ31: 0 | AK31: =AJ31*'BU FACILITIES'!$G$21 -> 0 | AL31: 0 | AM31: =PRODUCT( AL31,'BU FACILITIES'!$G$22) -> 0 | AN31: Si | AP31: =IF(AO31=1,'BU FACILITIES'!$G$23,"") | AQ31: 0 | AR31: 500 | AT31: 0 | AU31: 500 | AZ31: 0 | BA31: 3
A32: Plataforma OLT Equipo Nuevo | B32: BBI-TV-TOIP | C32: Income | D32: Gerencia Acceso Fijo | E32: Henry Campos | F32: 2023 | G32: Puerto Colombia | H32: Puerto Colombia | J32: Yes | K32: 2 | L32: 1 | M32: 842 | N32: 1403 | P32: =SUMIF($G$3:$G$316,G32,$N$3:$N$316) -> 2806 | Q32: =IF(N32<>0,N32/P32,"0") -> 0.5 | R32: =VLOOKUP(G32,#REF!,11,0)*Q32 -> #REF! | S32: DC | U32: 2 | V32: 0 | W32: 0 | X32: DC | Y32: 3 | Z32: Q3 | AB32: OLT nueva | AC32: Se buscará mejor sitio por seguridad, sitios movil han sido vandalizados | AE32: NO | AF32: SI | AI32: SI | AJ32: 0 | AK32: =AJ32*'BU FACILITIES'!$G$21 -> 0 | AL32: 0 | AM32: =PRODUCT( AL32,'BU FACILITIES'!$G$22) -> 0 | AN32: SI | AP32: =IF(AO32=1,'BU FACILITIES'!$G$23,"") | AQ32: 0 | AR32: 300 | AT32: 0 | AU32: 100 | AW32: 0 | AX32: 20
A33: Plataforma OLT Equipo Nuevo | B33: BBI-TV-TOIP | C33: Income | D33: Gerencia Acceso Fijo | E33: Henry Campos | F33: 2023 | G33: Jamundi | H33: Jamundí | J33: Yes | K33: 2 | L33: 1 | M33: 842 | N33: 1403 | P33: =SUMIF($G$3:$G$316,G33,$N$3:$N$316) -> 4209 | Q33: =IF(N33<>0,N33/P33,"0") -> 0.33333333 | R33: =VLOOKUP(G33,#REF!,11,0)*Q33 -> #REF! | S33: DC | U33: 2 | V33: 0 | W33: 0 | X33: DC | Y33: 3 | Z33: Q2 | AB33: OLT nueva | AC33: No se tiene esapcio ni capacidad en rectificadores y AA | AD33: 5 | AE33: NO | AK33: =AJ33*'BU FACILITIES'!$G$21 -> 0 | AL33: 0 | AM33: =PRODUCT( AL33,'BU FACILITIES'!$G$22) -> 0 | AP33: =IF(AO33=1,'BU FACILITIES'!$G$23,"")
A34: Plataforma RemotePhy Equipo Nuevo | B34: BBI-TV-TOIP | C34: Income | D34: Gerencia Acceso Fijo | E34: Jorge Mauricio | F34: 2023 | G34: Nuevo Nodo (Reemplzao ECE) | H34: Santa Marta | J34: Yes | K34: 1 | L34: 4 | M34: 2267 | N34: 2267 | P34: =SUMIF($G$3:$G$316,G34,$N$3:$N$316) -> 7340 | Q34: =IF(N34<>0,N34/P34,"0") -> 0.30885559 | R34: =VLOOKUP(G34,#REF!,11,0)*Q34 -> #REF! | S34: DC | U34: 8 | V34: 0 | W34: 0 | X34: DC | Y34: 1.5 | Z34: Q2 | AC34: Por conseguir el sitio | AE34: NO | AF34: No | AI34: No | AK34: =AJ34*'BU FACILITIES'!$G$21 -> 0 | AL34: 0 | AM34: =PRODUCT( AL34,'BU FACILITIES'!$G$22) -> 0 | AN34: No | AP34: =IF(AO34=1,'BU FACILITIES'!$G$23,"") | AQ34: =2*0 -> 0 | AR34: =300*0 -> 0
A35: Plataforma Óptica | B35: BBI-TV-TOIP | C35: Income | D35: Gerencia Acceso Fijo | E35: Jorge Ivan Pérez Cardona | F35: 2023 | G35: La Paz (Bosa) | H35: Bogotá | J35: Yes | K35: 1 | L35: 6 | M35: 475 | N35: 2850 | P35: =SUMIF($G$3:$G$316,G35,$N$3:$N$316) -> 5700 | Q35: =IF(N35<>0,N35/P35,"0") -> 0.5 | R35: =VLOOKUP(G35,#REF!,11,0)*Q35 -> #REF! | S35: DC | T35: 1620.75 | U35: 2 | X35: 48 VDC | Y35: 1.5 | Z35: Q1-Q2 | AB35: Transmisores y Receptotes Ópticos | AC35: No se tiene capacidad AC. Se debe realizar proyecto de aumento de capacidad con CODENSA | AE35: NO | AK35: =AJ35*'BU FACILITIES'!$G$21 -> 0 | AL35: 0 | AM35: =PRODUCT( AL35,'BU FACILITIES'!$G$22) -> 0 | AP35: =IF(AO35=1,'BU FACILITIES'!$G$23,"")
A36: Plataforma Óptica | B36: BBI-TV-TOIP | C36: Income | D36: Gerencia Acceso Fijo | E36: Jorge Ivan Pérez Cardona | F36: 2023 | G36: Linda Vista | H36: Barranquilla | J36: Yes | K36: 1 | L36: 2 | M36: 475 | N36: 950 | P36: =SUMIF($G$3:$G$316,G36,$N$3:$N$316) -> 1900 | Q36: =IF(N36<>0,N36/P36,"0") -> 0.5 | R36: =VLOOKUP(G36,#REF!,11,0)*Q36 -> #REF! | S36: DC | T36: 1620.75 | U36: 2 | X36: 48 VDC | Y36: 1.5 | Z36: Q1-Q2 | AB36: Transmisores y Receptotes Ópticos | AC36: Este nodo está en proceso de desmonte | AD36: 5 | AE36: NO | AK36: =AJ36*'BU FACILITIES'!$G$21 -> 0 | AL36: 0 | AM36: =PRODUCT( AL36,'BU FACILITIES'!$G$22) -> 0 | AP36: =IF(AO36=1,'BU FACILITIES'!$G$23,"")
A37: Plataforma Óptica | B37: BBI-TV-TOIP | C37: Income | D37: Gerencia Acceso Fijo | E37: Jorge Ivan Pérez Cardona | F37: 2023 | G37: Centro Ejecutivo | H37: Santa Marta | J37: Yes | K37: 1 | L37: 6 | M37: 475 | N37: 2850 | P37: =SUMIF($G$3:$G$316,G37,$N$3:$N$316) -> 8100 | Q37: =IF(N37<>0,N37/P37,"0") -> 0.35185185 | R37: =VLOOKUP(G37,#REF!,11,0)*Q37 -> #REF! | S37: DC | T37: 1620.75 | U37: 2 | X37: 48 VDC | Y37: 1.5 | Z37: Q1-Q2 | AB37: Transmisores y Receptotes Ópticos | AC37: Sitio sobrecargado energía y refrigeración | AD37: 4 | AE37: NO | AK37: =AJ37*'BU FACILITIES'!$G$21 -> 0 | AL37: 0 | AM37: =PRODUCT( AL37,'BU FACILITIES'!$G$22) -> 0 | AP37: =IF(AO37=1,'BU FACILITIES'!$G$23,"")
A38: Plataforma Óptica | B38: BBI-TV-TOIP | C38: Income | D38: Gerencia Acceso Fijo | E38: Jorge Ivan Pérez Cardona | F38: 2023 | G38: Camara de Comercio | H38: Armenia | K38: 1 | L38: 6 | M38: 475 | N38: 2850 | P38: =SUMIF($G$3:$G$316,G38,$N$3:$N$316) -> 5700 | Q38: =IF(N38<>0,N38/P38,"0") -> 0.5 | R38: =VLOOKUP(G38,#REF!,11,0)*Q38 -> #REF! | S38: DC | T38: 1620.75 | U38: 2 | X38: 48 VDC | Y38: 1.5 | Z38: Q1-Q2 | AB38: Transmisores y Receptotes Ópticos | AC38: Sitio sin espacio. No hay forma de ampliación. | AD38: 4 | AE38: No | AI38: Si | AJ38: 0 | AK38: =AJ38*'BU FACILITIES'!$G$21 -> 0 | AL38: 0 | AM38: =PRODUCT( AL38,'BU FACILITIES'!$G$22) -> 0 | AP38: =IF(AO38=1,'BU FACILITIES'!$G$23,"")
A39: Plataforma Óptica | B39: BBI-TV-TOIP | C39: Income | D39: Gerencia Acceso Fijo | E39: Jorge Ivan Pérez Cardona | F39: 2023 | G39: Cabecera | H39: Armenia | J39: Yes | K39: 1 | L39: 6 | M39: 475 | N39: 0 | P39: =SUMIF($G$3:$G$316,G39,$N$3:$N$316) -> 2850 | Q39: =IF(N39<>0,N39/P39,"0") -> 0 | R39: =VLOOKUP(G39,#REF!,11,0)*Q39 -> #REF! | S39: DC | T39: 1620.75 | U39: 2 | X39: 48 VDC | Y39: 1.5 | Z39: Q1-Q2 | AB39: Transmisores y Receptotes Ópticos | AC39: Sitio sin espacio. No hay forma de ampliación. | AD39: 4 | AE39: No | AK39: =AJ39*'BU FACILITIES'!$G$21 -> 0 | AL39: 0 | AM39: =PRODUCT( AL39,'BU FACILITIES'!$G$22) -> 0 | AP39: =IF(AO39=1,'BU FACILITIES'!$G$23,"")
A40: MPLS | B40: MPLS | C40: INCOME | D40: Gerencia Cloud, IP y DC | E40: José Alejandro Arcila | F40: 2023 | G40: Centro ejecutivo | H40: Santa Marta | J40: no | K40: 0 | L40: 0 | M40: 400 | N40: 600 | P40: =SUMIF($G$3:$G$316,G40,$N$3:$N$316) -> 8100 | Q40: =IF(N40<>0,N40/P40,"0") -> 0.074074074 | R40: =VLOOKUP(G40,#REF!,11,0)*Q40 -> #REF! | S40: dc | T40: 682 BTU/hour | AB40: Tarjeta 24*10 | AC40: Sitio sobrecargado energía y refrigeración | AD40: 4 | AE40: NO | AK40: =AJ40*'BU FACILITIES'!$G$21 -> 0 | AL40: 0 | AM40: =PRODUCT( AL40,'BU FACILITIES'!$G$22) -> 0 | AP40: =IF(AO40=1,'BU FACILITIES'!$G$23,"")
A41: MPLS | B41: MPLS | C41: INCOME | D41: Gerencia Cloud, IP y DC | E41: José Alejandro Arcila | F41: 2023 | G41: Nodo Nuevo | H41: Santa Marta | J41: si | K41: 1 | L41: 0 | M41: 400 | N41: 600 | P41: =SUMIF($G$3:$G$316,G41,$N$3:$N$316) -> 2400 | Q41: =IF(N41<>0,N41/P41,"0") -> 0.25 | R41: =VLOOKUP(G41,#REF!,11,0)*Q41 -> #REF! | S41: dc | T41: 992 BTU/hour | U41: 2 | AB41: Swiche DAAS | AC41: Por conseguir el sitio | AE41: NO | AK41: =AJ41*'BU FACILITIES'!$G$21 -> 0 | AL41: 0 | AM41: =PRODUCT( AL41,'BU FACILITIES'!$G$22) -> 0 | AP41: =IF(AO41=1,'BU FACILITIES'!$G$23,"")
...

Sheet Sitios sin inversión
A1: Platform or Equipment | B1: Associated Services to the platform | C1: Income / Dismount | D1: Responsable Technical Area | E1: Responsable Technician | F1: Year | G1: Technical Site | H1: City | I1: Regional | J1: Additional m2? Yes/No | K1: If Yes: # Racks? | L1: Quantity Equipment DC | M1: Average Power (W) | N1: Máx. Power DC (W) | O1: Potencia liberar | P1: Sumatoria W por sitio | Q1: % potencia / gerencia | R1: Inversion por gerencia / sitio | S1: Voltage (AC or DC) | T1: Air DissipationBTU | U1: Power sources | V1: Quantity Equipment AC | W1: Máx. Power AC (W) | X1: Voltage (AC or DC) | Y1: Requested Area (M2) | Z1: Instalation date | AA1: Prority | AB1: Comments | AC1: OBSERVACIÓN GERENCIA INFRAESTRUCTURA | AD1: tipo de NODO | AE1: PRE-Factibilidad Infraestructura (Si / No) | AF1: Obra eléctrica AC | AG1: Requiere obra eléctrica AC | AH1: Valor Obra eléctrica AC | AI1: Obra eléctrica DC | AJ1: Requiere Tablero PDB | AK1: Valor PDB | AL1: Requiere Energización | AM1: Valor Energización | AN1: Obra civil | AO1: Requiere obra civil | AP1: Valor Obra civil | AQ1: Rect Cantidad | AR1: Capacidad [Amperios] | AS1: Valor Rectificador | AT1: Bat Cantidad | AU1: Capacidad [Ah] | AV1: Valor Baterías | AW1: MG Cantidad | AX1: Capacidad [kVA] | AY1: Valor MG | AZ1: AA Cantidad | BA1: Capacidad [TR] | BB1: Valor equipos AA | BC1: Requiere rediseño de ductos | BD1: Valor rediseño ductos | BE1: Presupuesto Estimado
A2: Plataforma OLT Equipo Nuevo | B2: BBI-TV-TOIP | C2: Income | D2: Gerencia Acceso Fijo | E2: Henry Campos | F2: 2023 | G2: Centro EDATEL Puerto Berrio | H2: Puerto Berrío | I2: NOROCCIDENTE | J2: Yes | K2: 2 | L2: 1 | M2: 842 | N2: 0 | P2: 0 | Q2: 0 | R2: 0 | S2: DC | U2: 2 | V2: 0 | W2: 0 | X2: DC | Y2: 3 | Z2: Q2 | AB2: OLT nueva | AC2: Requiere BB2000AH y PDB, tiene MG | AE2: SI CONDICIONADA | AI2: PDB | AJ2: 1 | AK2: 1714.6341 | AL2: 1 | AM2: 870.73171 | AT2: 1 | AU2: 2000 | AV2: 21452.006
A3: Plataforma OLT Equipo Nuevo | B3: BBI-TV-TOIP | C3: Income | D3: Gerencia Acceso Fijo | E3: Henry Campos | F3: 2023 | G3: Centro EDATEL Segovia | H3: Segovia | I3: NOROCCIDENTE | J3: Yes | K3: 2 | L3: 1 | M3: 842 | N3: 0 | P3: 0 | Q3: 0 | R3: 0 | S3: DC | U3: 2 | V3: 0 | W3: 0 | X3: DC | Y3: 3 | Z3: Q2 | AB3: OLT nueva | AC3: Este 2022 se va a instalar un rect 300 A nuevo (Rolluot). Requiere nuevo BB 1000AH, tiene MG | AE3: SI CONDICIONADA | AI3: PDB | AJ3: 1 | AK3: 1714.6341 | AL3: 1 | AM3: 870.73171 | AT3: 1 | AU3: 1000 | AV3: 12831.91
